/var/spool/slurm/d/job161232/slurm_script: line 16: activate: No such file or directory
Traceback (most recent call last):
  File "/home/jocl/.conda/envs/lmeval/lib/python3.11/site-packages/huggingface_hub/utils/_errors.py", line 270, in hf_raise_for_status
    response.raise_for_status()
  File "/home/jocl/.conda/envs/lmeval/lib/python3.11/site-packages/requests/models.py", line 1021, in raise_for_status
    raise HTTPError(http_error_msg, response=self)
requests.exceptions.HTTPError: 401 Client Error: Unauthorized for url: https://huggingface.co/bigscience/bloom-7B/resolve/main/config.json

The above exception was the direct cause of the following exception:

Traceback (most recent call last):
  File "/home/jocl/.conda/envs/lmeval/lib/python3.11/site-packages/transformers/utils/hub.py", line 430, in cached_file
    resolved_file = hf_hub_download(
                    ^^^^^^^^^^^^^^^^
  File "/home/jocl/.conda/envs/lmeval/lib/python3.11/site-packages/huggingface_hub/utils/_validators.py", line 118, in _inner_fn
    return fn(*args, **kwargs)
           ^^^^^^^^^^^^^^^^^^^
  File "/home/jocl/.conda/envs/lmeval/lib/python3.11/site-packages/huggingface_hub/file_download.py", line 1374, in hf_hub_download
    raise head_call_error
  File "/home/jocl/.conda/envs/lmeval/lib/python3.11/site-packages/huggingface_hub/file_download.py", line 1247, in hf_hub_download
    metadata = get_hf_file_metadata(
               ^^^^^^^^^^^^^^^^^^^^^
  File "/home/jocl/.conda/envs/lmeval/lib/python3.11/site-packages/huggingface_hub/utils/_validators.py", line 118, in _inner_fn
    return fn(*args, **kwargs)
           ^^^^^^^^^^^^^^^^^^^
  File "/home/jocl/.conda/envs/lmeval/lib/python3.11/site-packages/huggingface_hub/file_download.py", line 1624, in get_hf_file_metadata
    r = _request_wrapper(
        ^^^^^^^^^^^^^^^^^
  File "/home/jocl/.conda/envs/lmeval/lib/python3.11/site-packages/huggingface_hub/file_download.py", line 402, in _request_wrapper
    response = _request_wrapper(
               ^^^^^^^^^^^^^^^^^
  File "/home/jocl/.conda/envs/lmeval/lib/python3.11/site-packages/huggingface_hub/file_download.py", line 426, in _request_wrapper
    hf_raise_for_status(response)
  File "/home/jocl/.conda/envs/lmeval/lib/python3.11/site-packages/huggingface_hub/utils/_errors.py", line 320, in hf_raise_for_status
    raise RepositoryNotFoundError(message, response) from e
huggingface_hub.utils._errors.RepositoryNotFoundError: 401 Client Error. (Request ID: Root=1-6576dac3-5f43761133da8b280b996d99;347cdc1a-a6d0-44ff-bc1b-46ddb6197d82)

Repository Not Found for url: https://huggingface.co/bigscience/bloom-7B/resolve/main/config.json.
Please make sure you specified the correct `repo_id` and `repo_type`.
If you are trying to access a private or gated repo, make sure you are authenticated.
Invalid username or password.

The above exception was the direct cause of the following exception:

Traceback (most recent call last):
  File "/home/jocl/lmeval/eval_single.py", line 43, in <module>
    eval_model(model_name)
  File "/home/jocl/lmeval/eval_single.py", line 17, in eval_model
    lm = get_model("hf-causal-experimental")(
         ^^^^^^^^^^^^^^^^^^^^^^^^^^^^^^^^^^^^
  File "/home/jocl/lmeval/lm-evaluation-harness/lm_eval/models/huggingface.py", line 204, in __init__
    self._config = self.AUTO_CONFIG_CLASS.from_pretrained(
                   ^^^^^^^^^^^^^^^^^^^^^^^^^^^^^^^^^^^^^^^
  File "/home/jocl/.conda/envs/lmeval/lib/python3.11/site-packages/transformers/models/auto/configuration_auto.py", line 1048, in from_pretrained
    config_dict, unused_kwargs = PretrainedConfig.get_config_dict(pretrained_model_name_or_path, **kwargs)
                                 ^^^^^^^^^^^^^^^^^^^^^^^^^^^^^^^^^^^^^^^^^^^^^^^^^^^^^^^^^^^^^^^^^^^^^^^^^
  File "/home/jocl/.conda/envs/lmeval/lib/python3.11/site-packages/transformers/configuration_utils.py", line 622, in get_config_dict
    config_dict, kwargs = cls._get_config_dict(pretrained_model_name_or_path, **kwargs)
                          ^^^^^^^^^^^^^^^^^^^^^^^^^^^^^^^^^^^^^^^^^^^^^^^^^^^^^^^^^^^^^
  File "/home/jocl/.conda/envs/lmeval/lib/python3.11/site-packages/transformers/configuration_utils.py", line 677, in _get_config_dict
    resolved_config_file = cached_file(
                           ^^^^^^^^^^^^
  File "/home/jocl/.conda/envs/lmeval/lib/python3.11/site-packages/transformers/utils/hub.py", line 451, in cached_file
    raise EnvironmentError(
OSError: bigscience/bloom-7B is not a local folder and is not a valid model identifier listed on 'https://huggingface.co/models'
If this is a private repository, make sure to pass a token having permission to this repo either by logging in with `huggingface-cli login` or by passing `token=<your_token>`

real	0m48.952s
user	0m6.072s
sys	0m2.136s
